<?xml version="1.0"?>
<robot xmlns:xacro="http://www.ros.org/wiki/xacro">

<xacro:include filename="inertial_macros.xacro" />


<material name="black">
<color rgba="0 0 0 1"/>
</material>
<material name="blue">
<color rgba="0.2 0.2 1 1"/>
</material>
<material name="white">
<color rgba="1 1 1 1"/>
</material>

<!-- BASE LINK -->

<link name="base_link">
</link>


<!-- NAVI LINK -->
<joint name="navi_joint" type="fixed">
<parent link="base_link"/>
<child link="navi"/>
<origin xyz="0.0625 0 0"/>
</joint>

<link name="navi">
   <visual>
        <origin xyz="0.2 0 0.125"/>
        <material name="white"/>
        <geometry>
            <box size="0.53 0.53 0.25"/>
        </geometry>
   </visual>
   <collision>
        <origin xyz="0.2 0 0.125"/>
        <geometry>
            <box size="0.53 0.53 0.25"/>
        </geometry>
   </collision>
   <xacro:inertial_box mass="15" x="0.53" y="0.53" z="0.25">
    <origin xyz="0.2 0 0.125" rpy="0 0 0"/>
   </xacro:inertial_box>
</link>

<gazebo reference="navi">
        <material>Gazebo/White</material>
</gazebo>

<!-- LEFT WHEEL LINK -->

    <joint name="left_wheel_joint" type="continuous">
        <parent link="base_link"/>
        <child link="left_wheel"/>
        <origin xyz="0.0625 0.235 0" rpy="-${pi/2} 0 0" />
        <axis xyz="0 0 1"/>
        <dynamics damping="0.2"/>
    </joint>

    <link name="left_wheel">
        <visual>
            <geometry>
                <cylinder radius="0.0625" length="0.03"/>
            </geometry>
            <material name="black"/>
        </visual>
        <collision>
            <geometry>
                <cylinder radius="0.0625" length="0.03"/>
            </geometry>
        </collision>
        <xacro:inertial_cylinder mass="0.3" length="0.03" radius="0.0625">
            <origin xyz="0 0 0" rpy="0 0 0"/>
        </xacro:inertial_cylinder>
    </link>
    
    <gazebo reference="left_wheel">
        <material>Gazebo/Black</material>
    </gazebo>

    <!-- RIGHT WHEEL LINK -->

    <joint name="right_wheel_joint" type="continuous">
        <parent link="base_link"/>
        <child link="right_wheel"/>
        <origin xyz="0.0625 -0.235 0" rpy="${pi/2} 0 0" />
        <axis xyz="0 0 -1"/>
    </joint>

    <link name="right_wheel">
        <visual>
            <geometry>
                <cylinder radius="0.0625" length="0.03"/>
            </geometry>
            <material name="black"/>
        </visual>
        <collision>
            <geometry>
                <cylinder radius="0.0625" length="0.03"/>
            </geometry>
        </collision>
        <xacro:inertial_cylinder mass="0.3" length="0.03" radius="0.0625">
            <origin xyz="0 0 0" rpy="0 0 0"/>
        </xacro:inertial_cylinder>
    </link>

    <gazebo reference="right_wheel">
        <material>Gazebo/Black</material>
    </gazebo>


    <!-- CASTER WHEEL LINK -->

    <joint name="caster_wheel_joint" type="fixed">
        <parent link="navi"/>
        <child link="caster_wheel"/>
        <origin xyz="0.3925 0 0"/>
    </joint>


    <link name="caster_wheel">
        <visual>
            <geometry>
                <sphere radius="0.0625"/>
            </geometry>
            <material name="black"/>
        </visual>
        <collision>
            <geometry>
                <sphere radius="0.0625"/>
            </geometry>
        </collision>
        <xacro:inertial_sphere mass="0.1" radius="0.05">
            <origin xyz="0 0 0" rpy="0 0 0"/>
        </xacro:inertial_sphere>
    </link>

    <gazebo reference="caster_wheel">
        <material>Gazebo/Black</material>
    </gazebo>


</robot>




